<?xml version="1.0"?>
<sdf version="1.6">
  <model name="roboboat01">
    <link name="base_link">
      <inertial>
        <pose>0 0 -0.2 0 0 0</pose>
        <mass>10</mass>
        <inertia>
          <ixx>0.5666666666666668</ixx>
          <ixy>0</ixy>
          <ixz>0</ixz>
          <iyy>1.0416666666666667</iyy>
          <iyz>0</iyz>
          <izz>1.5416666666666667</izz>
        </inertia>
      </inertial>
      <visual name="visual">
        <geometry>
           <mesh>
            <uri>file://roboboat01/meshes/roboboat01.dae</uri>
          </mesh>
        </geometry>
        <material>
          <diffuse>1.0 1.0 1.0</diffuse>
          <specular>1.0 1.0 1.0</specular>
          <pbr>
            <metal>
              <albedo_map>file://roboboat01/materials/textures/Boat01_Albedo.png</albedo_map>
              <normal_map>file://roboboat01/materials/textures/Boat01_Normal.png</normal_map>
              <roughness_map>file://roboboat01/materials/textures/Boat01_Roughness.png</roughness_map>
              <metalness_map>file://roboboat01/materials/textures/Boat01_Metallic.png</metalness_map>
            </metal>
          </pbr>
          <!-- fallback to script if no PBR support-->
          <script>
            <uri>file://roboboat01/materials/scripts/</uri>
            <uri>file://roboboat01/materials/textures/</uri>
            <name>Fallback/Boat01_Diffuse</name>
          </script>
        </material>
      </visual>

      <collision name="Box011">
        <pose>0.110046 0.314338 0.0352701 0.0 0.0 0.0</pose>
        <geometry>
          <box>
            <size>1.14985 0.223203 0.202172</size>
          </box>
        </geometry>
      </collision>
      <collision name="Box012">
        <pose>0.110046 -0.31434 0.0352701 0.0 0.0 0.0</pose>
        <geometry>
          <box>
            <size>1.14985 0.223203 0.202172</size>
          </box>
        </geometry>
      </collision>
      <collision name="Box013">
        <pose>0.0549115 0.0 0.240029 0.0 0.0 0.0</pose>
        <geometry>
          <box>
            <size>0.598409 0.459244 0.0260934</size>
          </box>
        </geometry>
      </collision>
      <collision name="Cylinder262">
        <pose>-0.158378 0.290814 0.162712 1.0472 0.0 0.0</pose>
        <geometry>
          <cylinder>
            <length>0.222664</length>
            <radius>0.0222591</radius>
          </cylinder>
        </geometry>
      </collision>
      <collision name="Cylinder263">
        <pose>-0.158378 -0.290814 0.162712 -1.0472 0.0 0.0</pose>
        <geometry>
          <cylinder>
            <length>0.222664</length>
            <radius>0.0222591</radius>
          </cylinder>
        </geometry>
      </collision>
      <collision name="Cylinder264">
        <pose>0.12101 0.290814 0.162712 1.0472 0.0 0.0</pose>
        <geometry>
          <cylinder>
            <length>0.222664</length>
            <radius>0.0222591</radius>
          </cylinder>
        </geometry>
      </collision>
      <collision name="Cylinder265">
        <pose>0.12101 -0.290814 0.162712 -1.0472 0.0 0.0</pose>
        <geometry>
          <cylinder>
            <length>0.222664</length>
            <radius>0.0222591</radius>
          </cylinder>
        </geometry>
      </collision>
      <collision name="Cylinder266">
        <pose>0.12101 -0.000654578 0.21655 1.5708 0.0 0.0</pose>
        <geometry>
          <cylinder>
            <length>0.409041</length>
            <radius>0.0155011</radius>
          </cylinder>
        </geometry>
      </collision>
      <collision name="Cylinder267">
        <pose>-0.15838 -0.000654578 0.21655 1.5708 0.0 0.0</pose>
        <geometry>
          <cylinder>
            <length>0.409041</length>
            <radius>0.0155011</radius>
          </cylinder>
        </geometry>
      </collision>

      <!-- CPU case -->
      <visual name="visual_cpubox">
        <pose>0.0 0.0 0.25 0 0 0</pose>
        <geometry>
           <mesh>
            <uri>file://roboboat_cpubox/meshes/drybox.dae</uri>
          </mesh>
        </geometry>
        <material>
          <diffuse>1.0 1.0 1.0</diffuse>
          <specular>1.0 1.0 1.0</specular>
          <pbr>
            <metal>
              <albedo_map>file://roboboat_cpubox/materials/textures/DryBox_Albedo.png</albedo_map>
              <roughness_map>file://roboboat_cpubox/materials/textures/DryBox_Roughness.png</roughness_map>
            </metal>
          </pbr>
        </material>
      </visual>
      <collision name="cpu_box">
        <pose>0 0 0.25 0 0 0</pose>
        <geometry>
          <box>
            <size>0.2 0.3 0.3</size>
          </box>
        </geometry>
      </collision>
    </link>

    <!-- Left thruster housing -->
    <link name="left_housing_link">
      <inertial>
        <pose>-0.3 0.33 -0.15 0 0 0</pose>
        <mass>1</mass>
        <inertia>
          <ixx>0.0020290833333333333</ixx>
          <ixy>0</ixy>
          <ixz>0</ixz>
          <iyy>0.002408333333333333</iyy>
          <iyz>0</iyz>
          <izz>0.0006874166666666666</izz>
        </inertia>
      </inertial>

      <visual name="left_housing_visual">
        <pose>-0.3 0.33 -0.15 0 0 0</pose>
        <geometry>
           <mesh>
            <uri>file://roboboat01/meshes/housing.dae</uri>
          </mesh>
        </geometry>
        <material>
          <diffuse>1.0 1.0 1.0</diffuse>
          <specular>1.0 1.0 1.0</specular>
          <pbr>
            <metal>
              <albedo_map>file://roboboat01/materials/textures/Thruster_Albedo.png</albedo_map>
              <roughness_map>file://roboboat01/materials/textures/Thruster_Roughness.png</roughness_map>
            </metal>
          </pbr>
        </material>
      </visual>

      <visual name="left_mount_visual">
        <pose>-0.3 0.33 -0.15 0 0 0</pose>
        <geometry>
           <mesh>
            <uri>file://roboboat01/meshes/mount.dae</uri>
          </mesh>
        </geometry>
        <material>
          <diffuse>1.0 1.0 1.0</diffuse>
          <specular>1.0 1.0 1.0</specular>
          <pbr>
            <metal>
              <albedo_map>file://roboboat01/materials/textures/Thruster_Albedo.png</albedo_map>
              <roughness_map>file://roboboat01/materials/textures/Thruster_Roughness.png</roughness_map>
            </metal>
          </pbr>
        </material>
      </visual>

      <collision name="Box011d">
        <pose>-0.3 0.33  -0.049048999999999995 0.0 0.0 0.0</pose>
        <geometry>
          <box>
            <size>0.0810453 0.0430519 0.070925</size>
          </box>
        </geometry>
      </collision>

      <collision name="Cylinder264d">
        <pose>-0.3 0.33 -0.08719339999999999 0.0 0.0 0.0</pose>
        <geometry>
          <cylinder>
            <length>0.125613</length>
            <radius>0.014703</radius>
          </cylinder>
        </geometry>
      </collision>
  
      <collision name="Cylinder263d">
        <pose>-0.2833463 0.32986701 -0.15 1.5708 0.0 -1.5708</pose>
        <geometry>
          <cylinder>
            <length>0.14376</length>
            <radius>0.0243692</radius>
          </cylinder>
        </geometry>
      </collision>
    </link>

    <!-- Left propeller -->
    <link name="left_prop_link">
      <inertial>
        <pose>-0.300872875 0.329867016 -0.15 1.5708 0.0 -1.5708</pose>
        <mass>0.1</mass>
        <inertia>
          <ixx>0.00010562499999999999</ixx>
          <ixy>0</ixy>
          <ixz>0</ixz>
          <iyy>0.00010562499999999999</iyy>
          <iyz>0</iyz>
          <izz>0.00015125000000000002</izz>
        </inertia>
      </inertial>
      <visual name="left_prop_visual">
        <pose>-0.3 0.33 -0.15 0 0 0</pose>
        <geometry>
           <mesh>
            <uri>file://roboboat01/meshes/prop.dae</uri>
          </mesh>
        </geometry>
        <material>
          <diffuse>1.0 1.0 1.0</diffuse>
          <specular>1.0 1.0 1.0</specular>
          <pbr>
            <metal>
              <albedo_map>file://roboboat01/materials/textures/Thruster_Albedo.png</albedo_map>
              <roughness_map>file://roboboat01/materials/textures/Thruster_Roughness.png</roughness_map>
            </metal>
          </pbr>
        </material>
      </visual>

      <collision name="Cylinder262d">
        <pose>-0.300872875 0.329867016 -0.15 1.5708 0.0 -1.5708</pose>
        <geometry>
          <cylinder>
            <length>0.0608172</length>
            <radius>0.0553844</radius>
          </cylinder>
        </geometry>
      </collision>
    </link>

    <!-- Right thruster housing -->
    <link name="right_housing_link">
      <inertial>
        <pose>-0.3 -0.33 -0.15 0 0 0</pose>
        <mass>1</mass>
        <inertia>
          <ixx>0.0020290833333333333</ixx>
          <ixy>0</ixy>
          <ixz>0</ixz>
          <iyy>0.002408333333333333</iyy>
          <iyz>0</iyz>
          <izz>0.0006874166666666666</izz>
        </inertia>
      </inertial>
      <visual name="right_housing_visual">
        <pose>-0.3 -0.33 -0.15 0 0 0</pose>
        <geometry>
           <mesh>
            <uri>file://roboboat01/meshes/housing.dae</uri>
          </mesh>
        </geometry>
        <material>
          <diffuse>1.0 1.0 1.0</diffuse>
          <specular>1.0 1.0 1.0</specular>
          <pbr>
            <metal>
              <albedo_map>file://roboboat01/materials/textures/Thruster_Albedo.png</albedo_map>
              <roughness_map>file://roboboat01/materials/textures/Thruster_Roughness.png</roughness_map>
            </metal>
          </pbr>
        </material>
      </visual>

      <visual name="right_mount_visual">
        <pose>-0.3 -0.33 -0.15 0 0 0</pose>
        <geometry>
           <mesh>
            <uri>file://roboboat01/meshes/mount.dae</uri>
          </mesh>
        </geometry>
        <material>
          <diffuse>1.0 1.0 1.0</diffuse>
          <specular>1.0 1.0 1.0</specular>
          <pbr>
            <metal>
              <albedo_map>file://roboboat01/materials/textures/Thruster_Albedo.png</albedo_map>
              <roughness_map>file://roboboat01/materials/textures/Thruster_Roughness.png</roughness_map>
            </metal>
          </pbr>
        </material>
      </visual>

      <!-- Thruster collisions -->
      <collision name="Box011i">
        <pose>-0.3 -0.33  -0.049048999999999995 0.0 0.0 0.0</pose>
        <geometry>
          <box>
            <size>0.0810453 0.0430519 0.070925</size>
          </box>
        </geometry>
      </collision>

      <collision name="Cylinder264i">
        <pose>-0.3 -0.33 -0.08719339999999999 0.0 0.0 0.0</pose>
        <geometry>
          <cylinder>
            <length>0.125613</length>
            <radius>0.014703</radius>
          </cylinder>
        </geometry>
      </collision>

      <collision name="Cylinder263i">
        <pose>-0.2833463 -0.32986701 -0.15 1.5708 0.0 -1.5708</pose>
        <geometry>
          <cylinder>
            <length>0.14376</length>
            <radius>0.0243692</radius>
          </cylinder>
        </geometry>
      </collision>
    </link>

    <!-- Right propeller -->
    <link name="right_prop_link">
      <inertial>
        <pose>-0.300872875 -0.329867016 -0.15 1.5708 0.0 -1.5708</pose>
        <mass>0.1</mass>
        <inertia>
          <ixx>0.00010562499999999999</ixx>
          <ixy>0</ixy>
          <ixz>0</ixz>
          <iyy>0.00010562499999999999</iyy>
          <iyz>0</iyz>
          <izz>0.00015125000000000002</izz>
        </inertia>
      </inertial>
      <visual name="right_prop_visual">
        <pose>-0.3 -0.33 -0.15 0 0 0</pose>
        <geometry>
           <mesh>
            <uri>file://roboboat01/meshes/prop.dae</uri>
          </mesh>
        </geometry>
        <material>
          <diffuse>1.0 1.0 1.0</diffuse>
          <specular>1.0 1.0 1.0</specular>
          <pbr>
            <metal>
              <albedo_map>file://roboboat01/materials/textures/Thruster_Albedo.png</albedo_map>
              <roughness_map>file://roboboat01/materials/textures/Thruster_Roughness.png</roughness_map>
            </metal>
          </pbr>
        </material>
      </visual>

      <collision name="Cylinder262i">
        <pose>-0.300872875 -0.329867016 -0.15 1.5708 0.0 -1.5708</pose>
        <geometry>
          <cylinder>
            <length>0.0608172</length>
            <radius>0.0553844</radius>
          </cylinder>
        </geometry>
      </collision>
    </link>

    <!-- Chassis-left engine joint -->
    <joint name="left_chasis_engine_joint" type="revolute">
      <axis>
        <xyz>0 0 1</xyz>
        <limit>
          <lower>0</lower>
          <upper>0</upper>
          <effort>10</effort>
          <velocity>10</velocity>
        </limit>
      </axis>
      <parent>base_link</parent>
      <child>left_housing_link</child>
    </joint>

    <!-- Left joint housing-propeller -->
    <joint name="left_engine_propeller_joint" type="revolute">
      <pose>-0.300872875 0.329867016 -0.15 1.5708 0.0 0</pose>
      <axis>
        <xyz>1 0 0</xyz>
        <limit>
          <effort>100</effort>
          <velocity>100</velocity>
        </limit>
        <dynamics>
          <friction>0.05</friction>
          <damping>0.05</damping>
        </dynamics>
      </axis>
      <parent>left_housing_link</parent>
      <child>left_prop_link</child>
    </joint>

    <!-- Chassis-right engine joint -->
    <joint name="right_chasis_engine_joint" type="revolute">
      <axis>
        <xyz>0 0 1</xyz>
        <limit>
          <lower>0</lower>
          <upper>0</upper>
          <effort>10</effort>
          <velocity>10</velocity>
        </limit>
      </axis>
      <parent>base_link</parent>
      <child>right_housing_link</child>
    </joint>

    <!-- Right joint housing-propeller -->
    <joint name="right_engine_propeller_joint" type="revolute">
      <pose>-0.300872875 -0.329867016 -0.15 1.5708 0.0 0</pose>
      <axis>
        <xyz>1 0 0</xyz>
        <limit>
          <effort>100</effort>
          <velocity>100</velocity>
        </limit>
        <dynamics>
          <friction>0.05</friction>
          <damping>0.05</damping>
        </dynamics>
      </axis>
      <parent>right_housing_link</parent>
      <child>right_prop_link</child>
    </joint>

    <!-- Left hull -->
    <plugin
      filename="libSurface.so"
      name="vrx::Surface">
      <link_name>base_link</link_name>
      <hull_length>1.15</hull_length>
      <hull_radius>0.12</hull_radius>
      <fluid_level>0.1</fluid_level>
      <points>
        <point>0.68 0.314338 0.0352701</point>
        <point>-0.465 0.314338 0.0352701</point>
      </points>
      <wavefield>
        <topic>/vrx/wavefield/parameters</topic>
      </wavefield>
    </plugin>

    <!-- Right hull -->
    <plugin
      filename="libSurface.so"
      name="vrx::Surface">
      <link_name>base_link</link_name>
      <hull_length>1.15</hull_length>
      <hull_radius>0.12</hull_radius>
      <fluid_level>0.1</fluid_level>
      <points>
        <point>0.68 -0.314338 0.0352701</point>
        <point>-0.465 -0.314338 0.0352701</point>
      </points>
      <wavefield>
        <topic>/vrx/wavefield/parameters</topic>
      </wavefield>
    </plugin>

    <plugin
      filename="libSimpleHydrodynamics.so"
      name="vrx::SimpleHydrodynamics">
      <link_name>base_link</link_name>
      <!-- Added mass -->
      <xDotU>0.0</xDotU>
      <yDotV>0.0</yDotV>
      <nDotR>0.0</nDotR>
      <!-- Linear and quadratic drag -->
      <xU>4.0</xU>
      <xUU>6.0</xUU>
      <yV>4.0</yV>
      <yVV>4.0</yVV>
      <zW>20.0</zW>
      <kP>12.0</kP>
      <kPP>24.0</kPP>
      <mQ>36.0</mQ>
      <mQQ>35.0</mQQ>
      <nR>32.0</nR>
      <nRR>32.0</nRR>
    </plugin>

    <plugin
      filename="gz-sim-thruster-system"
      name="gz::sim::systems::Thruster">
      <joint_name>left_engine_propeller_joint</joint_name>
      <thrust_coefficient>0.0001</thrust_coefficient>
      <fluid_density>1000</fluid_density>
      <propeller_diameter>0.1</propeller_diameter>
      <velocity_control>true</velocity_control>
    </plugin>

    <plugin
      filename="gz-sim-thruster-system"
      name="gz::sim::systems::Thruster">
      <joint_name>right_engine_propeller_joint</joint_name>
      <thrust_coefficient>0.0001</thrust_coefficient>
      <fluid_density>1000</fluid_density>
      <propeller_diameter>0.1</propeller_diameter>
      <velocity_control>true</velocity_control>
    </plugin>

  </model>
</sdf>
