<?xml version="1.0"?>
<!-- Basic WAM-V with gazebo plugins for dynamics -->
<robot xmlns:xacro="http://ros.org/wiki/xacro"
       name="WAM-V">
  <xacro:arg name="locked" default="false" />
  <xacro:arg name="thruster_config" default="H" />
  <xacro:arg name="camera_enabled" default="false" />
  <xacro:arg name="gps_enabled" default="false" />
  <xacro:arg name="imu_enabled" default="false" />
  <xacro:arg name="lidar_enabled" default="false" />
  <xacro:arg name="ground_truth_enabled" default="false" />
  <xacro:arg name="vrx_sensors_enabled" default="false" />

  <!-- === The WAM-V platform === -->
  <xacro:include filename="$(find wamv_gazebo)/urdf/wamv_gazebo.xacro"/>
  
  <!-- === Batteries === -->
  <xacro:include filename="$(find wamv_description)/urdf/battery.xacro"/>
  <xacro:battery prefix="left" position="0 1 0.45" orientation="0 0 0"/>
  <xacro:battery prefix="right" position="0 -1 0.45" orientation="0 0 0"/>

  <!-- === Thrusters === -->
  <xacro:property name="thruster_conf" value="$(arg thruster_config)"/>

  <!-- Default WAM-V with two aft thrusters -->
  <xacro:if value="${thruster_conf == 'H'}">
     <xacro:wamv_gazebo thruster_layout="$(find wamv_gazebo)/urdf/thruster_layouts/wamv_aft_thrusters.xacro"/>
  </xacro:if>

  <!-- WAMV with "T" thruster configuration -->
  <xacro:if value="${thruster_conf == 'T'}">
    <xacro:wamv_gazebo thruster_layout="$(find wamv_gazebo)/urdf/thruster_layouts/wamv_t_thrusters.xacro"/>
  </xacro:if>

  <!-- WAMV with "X" thruster configuration -->
  <xacro:if value="${thruster_conf == 'X'}">
    <xacro:wamv_gazebo thruster_layout="$(find wamv_gazebo)/urdf/thruster_layouts/wamv_x_thrusters.xacro"/>
  </xacro:if>

  <!-- Decide if we lock the robot to the world -->
  <xacro:if value="$(arg locked)">
    <gazebo>
      <link name="wamv_external_link"/>
      <joint name="wamv_external_pivot_joint" type="universal">
        <parent>wamv::base_link</parent>
        <child>wamv_external_link</child>
        <axis>
          <xyz>1 0 0</xyz>
        </axis>
        <axis2>
          <xyz>0 1 0</xyz>
        </axis2>
      </joint>
      <joint name="wamv_external_riser" type="prismatic">
        <parent>world</parent>
        <child>wamv_external_link</child>
        <axis>
          <limit>
            <lower>-3</lower>
            <upper>3</upper>
          </limit>
          <xyz>0 0 1</xyz>
        </axis>
      </joint>
    </gazebo>
  </xacro:if>

  <!-- ==== VRX sensor configuration ==== -->
  <xacro:if value="$(arg vrx_sensors_enabled)">

    <!-- Add CPU Cases -->
    <xacro:include filename="$(find wamv_description)/urdf/cpu_cases.xacro" />
    <xacro:cpu_cases position="-0.15 0 1.53" orientation="0 0 0"/>
  </xacro:if>

  <!-- === Sensors === -->
  <xacro:include filename="$(find wamv_description)/urdf/sensors.xacro"/>
  <xacro:sensors/>
</robot>
