<?xml version="1.0"?>
<!-- Basic WAM-V with gazebo plugins for dynamics -->
<robot xmlns:xacro="http://ros.org/wiki/xacro"
       name="WAM-V">
  <xacro:arg name="locked" default="false" />
  <xacro:arg name="thruster_config" default="H" />
  <xacro:arg name="camera_enabled" default="false" />
  <xacro:arg name="gps_enabled" default="false" />
  <xacro:arg name="imu_enabled" default="false" />
  <xacro:arg name="lidar_enabled" default="false" />
  <xacro:arg name="ground_truth_enabled" default="false" />
  <xacro:arg name="vrx_sensors_enabled" default="false" />

  <!-- === The WAM-V platform === -->
  <xacro:include filename="$(find wamv_gazebo)/urdf/wamv_gazebo.xacro" />

  <!-- === Thrusters === -->
  <xacro:property name="thruster_conf" value="$(arg thruster_config)"/> -->

  <!-- Default WAM-V with two aft thrusters -->
  <xacro:if value="${thruster_conf == 'H'}">
     <xacro:wamv_gazebo thruster_layout="$(find wamv_gazebo)/urdf/thruster_layouts/wamv_aft_thrusters.xacro"/>
  </xacro:if>

  <!-- WAMV with "T" thruster configuration -->
  <xacro:if value="${thruster_conf == 'T'}">
    <xacro:wamv_gazebo thruster_layout="$(find wamv_gazebo)/urdf/thruster_layouts/wamv_t_thrusters.xacro"/>
  </xacro:if>

  <!-- WAMV with "X" thruster configuration -->
  <xacro:if value="${thruster_conf == 'X'}">
    <xacro:wamv_gazebo thruster_layout="$(find wamv_gazebo)/urdf/thruster_layouts/wamv_x_thrusters.xacro"/>
  </xacro:if>

  <!-- Decide if we lock the robot to the world -->
  <xacro:if value="$(arg locked)">
    <gazebo>
      <link name="wamv_external_link"/>
      <joint name="wamv_external_pivot_joint" type="universal">
        <parent>wamv::base_link</parent>
        <child>wamv_external_link</child>
        <axis>
          <xyz>1 0 0</xyz>
        </axis>
        <axis2>
          <xyz>0 1 0</xyz>
        </axis2>
      </joint>
      <joint name="wamv_external_riser" type="prismatic">
        <parent>world</parent>
        <child>wamv_external_link</child>
        <axis>
          <limit>
            <lower>-3</lower>
            <upper>3</upper>
          </limit>
          <xyz>0 0 1</xyz>
        </axis>
      </joint>
    </gazebo>
  </xacro:if>

  <!-- Add a front camera -->
  <xacro:wamv_camera name="front_camera" y="0.3" x="0.75" P="${radians(15)}" />

  <!-- Add 2D LIDAR -->
  <xacro:wamv_multibeam_laser name="planar_lidar" />

  <!-- Add simulated GPS -->
  <!-- <xacro:wamv_gps name="gps_wamv" y="0.2" /> -->

  <!-- Add Simulated IMU -->
  <!-- <xacro:wamv_imu name="imu_wamv" y="-0.2" /> -->

</robot>
