<?xml version="1.0"?>
<sdf version="1.6">
  <model name="roboboat_thruster">
    <static>true</static>
    <pose>0 0 0 0 0 0</pose>
    <link name="housing_link">
      <inertial>
        <pose>0 0 -0.2 0 0 0</pose>
        <mass>6.715</mass>
        <inertia>
          <ixx>1.3486</ixx>
          <ixy>0</ixy>
          <ixz>0</ixz>
          <iyy>1.3486</iyy>
          <iyz>0</iyz>
          <izz>2.51813</izz>
        </inertia>
      </inertial>

      <!-- Collisions -->
      <collision name="Box011i">
        <pose>0 0 0.100951 0 0 0</pose>
        <geometry>
          <box>
            <size>0.0810453 0.0430519 0.070925</size>
          </box>
        </geometry>
      </collision>

      <collision name="Cylinder264i">
        <pose>0 0 0.0628066 0 0 0</pose>
        <geometry>
          <cylinder>
            <length>0.125613</length>
            <radius>0.014703</radius>
          </cylinder>
        </geometry>
      </collision>

      <collision name="Cylinder263i">
        <pose>0.016653699999999994 0.0001329899999999995 0 1.5708 0.0 -1.5708</pose>
        <geometry>
          <cylinder>
            <length>0.14376</length>
            <radius>0.0243692</radius>
          </cylinder>
        </geometry>
      </collision>

      <!-- Visuals -->
      <visual name="visual_housing">
        <geometry>
           <mesh>
            <uri>file://roboboat_thruster/meshes/housing.dae</uri>
          </mesh>
        </geometry>
        <material>
          <diffuse>1.0 1.0 1.0</diffuse>
          <specular>1.0 1.0 1.0</specular>
          <pbr>
            <metal>
              <albedo_map>file://roboboat_thruster/materials/textures/Thruster_Albedo.png</albedo_map>
              <roughness_map>file://roboboat_thruster/materials/textures/Thruster_Roughness.png</roughness_map>
            </metal>
          </pbr>
        </material>
      </visual>

      <visual name="visual_mount">
        <geometry>
           <mesh>
            <uri>file://roboboat_thruster/meshes/mount.dae</uri>
          </mesh>
        </geometry>
        <material>
          <diffuse>1.0 1.0 1.0</diffuse>
          <specular>1.0 1.0 1.0</specular>
          <pbr>
            <metal>
              <albedo_map>file://roboboat_thruster/materials/textures/Thruster_Albedo.png</albedo_map>
              <roughness_map>file://roboboat_thruster/materials/textures/Thruster_Roughness.png</roughness_map>
            </metal>
          </pbr>
        </material>
      </visual>

      
    </link>

    <!-- The prop -->
    <link name="propeller_link">
      <visual name="visual_prop">
        <geometry>
           <mesh>
            <uri>file://roboboat_thruster/meshes/prop.dae</uri>
          </mesh>
        </geometry>
        <material>
          <diffuse>1.0 1.0 1.0</diffuse>
          <specular>1.0 1.0 1.0</specular>
          <pbr>
            <metal>
              <albedo_map>file://roboboat_thruster/materials/textures/Thruster_Albedo.png</albedo_map>
              <roughness_map>file://roboboat_thruster/materials/textures/Thruster_Roughness.png</roughness_map>
            </metal>
          </pbr>
        </material>
      </visual>
      <collision name="Cylinder262i">
        <pose>-0.0008728749999999952 0.00013298400000000266 0 1.5708 0.0 -1.5708</pose>
        <geometry>
          <cylinder>
            <length>0.0608172</length>
            <radius>0.0553844</radius>
          </cylinder>
        </geometry>
      </collision>
      <inertial>
        <mass value="0.05"/>
        <inertia ixx="0.0008545" ixy="0.0" ixz="0.0" iyy="0.0008545" iyz="0.0" izz="0.00144"/>
      </inertial>
    </link>

    <!-- Joint housing-propeller -->
    <joint name="left_engine_propeller_joint" type="revolute">
      <axis>
        <xyz>1 0 0</xyz>
        <limit>
          <effort>100</effort>
          <velocity>100</velocity>
        </limit>
        <dynamics>
          <friction>0.05</friction>
          <damping>0.05</damping>
        </dynamics>
      </axis>
      <parent>housing_link</parent>
      <child>propeller_link</child>
    </joint>

  </model>
</sdf>
