<?xml version="1.0"?>
<robot xmlns:xacro="http://ros.org/wiki/xacro">

  <!-- Dummy link, which usv_gazebo_thrust_plugin looks for -->
  <link name="engine_link">
    <inertial>
      <mass value="0.1"/>
      <inertia ixx="0.00889245" ixy="0.0" ixz="0.0" iyy="0.00911125" iyz="0.0" izz="0.00078125"/>
    </inertial>
  </link>

  <!-- No additional collision, since propeller is inside robot body -->
  <link name="propeller_link">
    <visual>
      <geometry>
        <mesh filename="package://sandwich_description/models/propeller/propeller.dae"/>
      </geometry>
    </visual>
    <inertial>
      <mass value="0.5"/>
      <inertia ixx="0.008545" ixy="0.0" ixz="0.0" iyy="0.008545" iyz="0.0" izz="0.0144"/>
    </inertial>
  </link>

  <!-- Dummy joint, which usv_gazebo_thrust_plugin looks for -->
  <joint name="engine_joint" type="revolute">
    <axis xyz="0 0 1"/>
    <origin rpy="0 0 0" xyz="-6.103 0.911 0.016"/>
    <parent link="sandwich/base_link"/>
    <child link="engine_link"/>
    <limit lower="${-pi}" upper="${pi}" effort="10" velocity="10"/>
  </joint>

  <joint name="engine_propeller_joint" type="continuous">
    <axis rpy="0 0 0" xyz="1 0 0"/>
    <origin xyz="0 0 0" rpy="0 0 0"/>
    <parent link="engine_link"/>
    <child link="propeller_link"/>
    <limit effort="100" velocity="100" />
    <dynamics friction="0.05" damping="0.05" />
  </joint>

  <gazebo>
    <plugin name="sandwich_gazebo_thrust" filename="libusv_gazebo_thrust_plugin.so">
      <cmdTimeout>1.0</cmdTimeout>
      <robotNamespace>sandwich</robotNamespace>
      <xacro:include filename="$(find sandwich_description)/urdf/sandwich_thruster_config.xacro" />
      <!-- Angle must be disabled for VORC -->
      <!-- <xacro:cora_thruster_config name="left" /> -->
    </plugin>
  </gazebo>

</robot>
